Workbook

Sheet Appraisal Form - NETS KHLC
F2: Employee Performance Appraisal Form 2026
F4: Employee ID | H4: Employee Name | N4: Employee Designation | X4: Grade Level
F5: 260301 | H5: =VLOOKUP($F5,Sheet1!$A:$F,2,0) -> EMMANUEL VICTOR OKON | N5: =VLOOKUP($F5,Sheet1!$A:$F,3,0) -> Head of Operations Lagos | X5: =VLOOKUP($F5,Sheet1!$A:$F,4,0) -> -
F7: Employment Date | H7: Department | N7: Sub Dept | R7: Appraisal Review Period (FROM) | X7: TO
F8: =VLOOKUP($F5,Sheet1!$A:$F,5,0) -> 44378 | H8: =VLOOKUP($F5,Sheet1!$A:$F,6,0) -> Fleet | N8: =VLOOKUP(F5,Sheet1!A:F,7,0) -> #REF! | R8: 46023 | X8: 46112
C12: COMPANY'S MISSION
C16: APPRAISAL INSTRUCTION | F16: The performance appraisal form follows the basic principles of effectively evaluating employee performance and is intended to providing employees objective feedback
F18: Please carefully review the employee’s performance during the review period and provide supporting comments and examples for each performance area. The performance appraisal should indicate the quality of performance and areas which may require further training and professional development.
C22: RATING LEVELS | F22: Singularly Exceptional | H22: 5 | J22: 100% & Above | L22: Performance is consistently extraordinary and is sustained at a level well beyond that of even other excellent employees | AB22: 0 | AC22: 0.3999 | AD22: 1
AB23: 0.4 | AC23: 0.5999 | AD23: 2
F24: Excellent | H24: 4 | J24: 80% - 99.9% | L24: Performance is consistently better than that expected of a fully proficient employee | AB24: 0.6 | AC24: 0.7999 | AD24: 3
AB25: 0.8 | AC25: 0.9999 | AD25: 4
F26: Fully Proficient | H26: 3 | J26: 60% - 79.9% | L26: Performance meets the full expectation of an employee for this job classification | AB26: 1 | AD26: 5
F28: Needs Improvement | H28: 2 | J28: 40% - 59.9% | L28: Performance is less than that of a fully proficient employee. Improvement is necessary.
F30: Not Working Out | H30: 1 | J30: Less than 40% | L30: Performance does not meet the minimum job requirements. Immediate and substantial improvement is necessary. Performance plan required immediately.
C33: GOAL 1: Employee and line manager should rate the appraisee's performance between 1 - 5. Final rating will pop automatically
C34: Functional Goal/ KPI | F34: Sub Goals/ Activities | H34: Weight age | J34: Target/ Expectation/ Measurement Parameters | L34: Achievements | P34: Emp Rating Score | Q34: 2 | R34: Line Mgr Rating Score | T34: Final Rating Score | V34: Final Rating % | X34: Final Rating Category
H36: 0.05 | P36: 5 | R36: 2 | T36: =ROUNDUP(((0*$P36)+(100%*$R36)),0) -> 2 | V36: =T36/5 -> 0.4 | X36: =IF($T36<1,"",(IF($T36=1,"Not Working Out",(IF($T36=2,"Needs Improvement",(IF($T36=3,"Fully Proficient",(IF($T36=4,"Excellent",(IF($T36=5,"Singularly Exceptional",""))))))))))) -> Needs Improvement
H37: 0.05 | P37: 4 | R37: 3 | T37: =ROUNDUP(((0*$P37)+(100%*$R37)),0) -> 3 | V37: =T37/5 -> 0.6 | X37: =IF($T37<1,"",(IF($T37=1,"Not Working Out",(IF($T37=2,"Needs Improvement",(IF($T37=3,"Fully Proficient",(IF($T37=4,"Excellent",(IF($T37=5,"Singularly Exceptional",""))))))))))) -> Fully Proficient
H38: 0.05 | P38: 3 | R38: 5 | T38: =ROUNDUP(((0*$P38)+(100%*$R38)),0) -> 5 | V38: =IF($T38<1,0,(IF($T38=1,49%,(IF($T38=2,50%,(IF($T38=3,70%,(IF($T38=4,90%,(IF($T38=5,100%,""))))))))))) -> 1 | X38: =IF($T38<1,"",(IF($T38=1,"Not Working Out",(IF($T38=2,"Needs Improvement",(IF($T38=3,"Fully Proficient",(IF($T38=4,"Excellent",(IF($T38=5,"Singularly Exceptional",""))))))))))) -> Singularly Exceptional
H39: 0.05 | P39: 4 | R39: 2 | T39: =ROUNDUP(((0*$P39)+(100%*$R39)),0) -> 2 | V39: =IF($T39<1,0,(IF($T39=1,49%,(IF($T39=2,50%,(IF($T39=3,70%,(IF($T39=4,90%,(IF($T39=5,100%,""))))))))))) -> 0.5 | X39: =IF($T39<1,"",(IF($T39=1,"Not Working Out",(IF($T39=2,"Needs Improvement",(IF($T39=3,"Fully Proficient",(IF($T39=4,"Excellent",(IF($T39=5,"Singularly Exceptional",""))))))))))) -> Needs Improvement
H40: =SUM(H36:H39) -> 0.2 | P40: =SUM(P36:P39) -> 16 | Q40: 3 | R40: =SUM(R36:R39) -> 12 | T40: =SUM(T36:T39) -> 12 | V40: =IFERROR(((T40/20)*$H40),0) -> 0.12
C44: GOAL 2: Employee and line manager should rate the appraisee's performance between 1 - 5. Final rating will pop automatically
C45: Functional Goal/ KPI | F45: Sub Goals/ Activities | H45: Weight age | J45: Target/ Expectation/ Measurement Parameters | L45: Achievements | P45: Emp Rating Score | R45: Line Mgr Rating Score | T45: Final Rating Score | V45: Final Rating % | X45: Final Rating Category
H47: 0.05 | P47: 4 | R47: 2 | T47: =ROUNDUP(((0*$P47)+(100%*$R47)),0) -> 2 | V47: =T47/5 -> 0.4 | X47: =IF($T47<1,"",(IF($T47=1,"Not Working Out",(IF($T47=2,"Needs Improvement",(IF($T47=3,"Fully Proficient",(IF($T47=4,"Excellent",(IF($T47=5,"Singularly Exceptional",""))))))))))) -> Needs Improvement
H48: 0.05 | P48: 5 | R48: 2 | T48: =ROUNDUP(((0*$P48)+(100%*$R48)),0) -> 2 | V48: =T48/5 -> 0.4 | X48: =IF($T48<1,"",(IF($T48=1,"Not Working Out",(IF($T48=2,"Needs Improvement",(IF($T48=3,"Fully Proficient",(IF($T48=4,"Excellent",(IF($T48=5,"Singularly Exceptional",""))))))))))) -> Needs Improvement
H49: 0.05 | T49: =ROUNDUP(((0*$P49)+(100%*$R49)),0) -> 0 | V49: =T49/5 -> 0 | X49: =IF($T49<1,"",(IF($T49=1,"Not Working Out",(IF($T49=2,"Needs Improvement",(IF($T49=3,"Fully Proficient",(IF($T49=4,"Excellent",(IF($T49=5,"Singularly Exceptional","")))))))))))
H50: 0.05 | T50: =ROUNDUP(((0*$P50)+(100%*$R50)),0) -> 0 | V50: =T50/5 -> 0 | X50: =IF($T50<1,"",(IF($T50=1,"Not Working Out",(IF($T50=2,"Needs Improvement",(IF($T50=3,"Fully Proficient",(IF($T50=4,"Excellent",(IF($T50=5,"Singularly Exceptional","")))))))))))
H51: =SUM(H47:H50) -> 0.2 | P51: =SUM(P47:P50) -> 9 | Q51: 3 | R51: =SUM(R47:R50) -> 4 | T51: =SUM(T47:T50) -> 4 | V51: =IFERROR(((T51/20)*$H51),0) -> 0.04
C55: GOAL 3: Employee and line manager should rate the appraisee's performance between 1 - 5. Final rating will pop automatically
C56: Functional Goal/ KPI | F56: Sub Goals/ Activities | H56: Weight age | J56: Target/ Expectation/ Measurement Parameters | L56: Achievements | P56: Emp Rating Score | R56: Line Mgr Rating Score | T56: Final Rating Score | V56: Final Rating % | X56: Final Rating Category
H58: 0.05 | P58: 5 | R58: 2 | T58: =ROUNDUP(((0*$P58)+(100%*$R58)),0) -> 2 | V58: =T58/5 -> 0.4 | X58: =IF($T58<1,"",(IF($T58=1,"Not Working Out",(IF($T58=2,"Needs Improvement",(IF($T58=3,"Fully Proficient",(IF($T58=4,"Excellent",(IF($T58=5,"Singularly Exceptional",""))))))))))) -> Needs Improvement
H59: 0.05 | T59: =ROUNDUP(((0*$P59)+(100%*$R59)),0) -> 0 | V59: =T59/5 -> 0 | X59: =IF($T59<1,"",(IF($T59=1,"Not Working Out",(IF($T59=2,"Needs Improvement",(IF($T59=3,"Fully Proficient",(IF($T59=4,"Excellent",(IF($T59=5,"Singularly Exceptional","")))))))))))
H60: 0.05 | T60: =ROUNDUP(((0*$P60)+(100%*$R60)),0) -> 0 | V60: =T60/5 -> 0 | X60: =IF($T60<1,"",(IF($T60=1,"Not Working Out",(IF($T60=2,"Needs Improvement",(IF($T60=3,"Fully Proficient",(IF($T60=4,"Excellent",(IF($T60=5,"Singularly Exceptional","")))))))))))
H61: 0.05 | T61: =ROUNDUP(((0*$P61)+(100%*$R61)),0) -> 0 | V61: =T61/5 -> 0 | X61: =IF($T61<1,"",(IF($T61=1,"Not Working Out",(IF($T61=2,"Needs Improvement",(IF($T61=3,"Fully Proficient",(IF($T61=4,"Excellent",(IF($T61=5,"Singularly Exceptional","")))))))))))
H62: =SUM(H58:H61) -> 0.2 | P62: =SUM(P58:P61) -> 5 | Q62: 3 | R62: =SUM(R58:R61) -> 2 | T62: =SUM(T58:T61) -> 2 | V62: =IFERROR(((T62/20)*$H62),0) -> 0.02
C66: GOAL 4: Employee and line manager should rate the appraisee's performance between 1 - 5. Final rating will pop automatically
C67: Functional Goal/ KPI | F67: Sub Goals/ Activities | H67: Weight age | J67: Target/ Expectation/ Measurement Parameters | L67: Achievements | P67: Emp Rating Score | R67: Line Mgr Rating Score | T67: Final Rating Score | V67: Final Rating % | X67: Final Rating Category
H69: 0.05 | P69: 4 | R69: 2 | T69: =ROUNDUP(((0*$P69)+(100%*$R69)),0) -> 2 | V69: =T69/5 -> 0.4 | X69: =IF($T69<1,"",(IF($T69=1,"Not Working Out",(IF($T69=2,"Needs Improvement",(IF($T69=3,"Fully Proficient",(IF($T69=4,"Excellent",(IF($T69=5,"Singularly Exceptional",""))))))))))) -> Needs Improvement
H70: 0.05 | T70: =ROUNDUP(((0*$P70)+(100%*$R70)),0) -> 0 | V70: =T70/5 -> 0 | X70: =IF($T70<1,"",(IF($T70=1,"Not Working Out",(IF($T70=2,"Needs Improvement",(IF($T70=3,"Fully Proficient",(IF($T70=4,"Excellent",(IF($T70=5,"Singularly Exceptional","")))))))))))
...

Sheet Sheet1
A1: Emp. ID | B1: EMP NAME | C1: EMP DESIGNATION | D1: GRADE LEVEL | E1: EMPLOYMENT DATE | F1: DEPT | G1: Company | H1: Location
A2: Insert Your Emp. Code | B2: Employee Name | C2: Employee Designation | D2: Grade Level | E2: Employment Date | F2: Department | G2: Company | H2: Location
A3: 260301 | B3: EMMANUEL VICTOR OKON | C3: Head of Operations Lagos | D3: - | E3: 44378 | F3: Fleet | G3: NETS | H3: Lagos
A4: 260302 | B4: ENEANOH MMACHIMEREM UGONNA | C4: Regional Head of Operations | D4: - | E4: 42036 | F4: Fleet | G4: NETS | H4: South East
A5: 260303 | B5: SAMALI UMORU JAMES | C5: Fleet Manager Ibadan | D5: - | E5: 44986 | F5: Fleet | G5: NETS | H5: Ibadan
A6: 260304 | B6: BUORO ABUBAKAR IDRIS | C6: Fleer Manager Kano | D6: - | E6: 43841 | F6: Fleet | G6: NETS | H6: Kano
A7: 260305 | B7: ASIEGBU CHIOMA JOHN | C7: Marketing Executive/CSR | D7: - | E7: 44958 | F7: Marketing | G7: NETS | H7: Lagos
A8: 260306 | B8: SAHEED AKANBI YUSUF | C8: Facility Manager | D8: - | E8: 45257 | F8: Fleet | G8: NETS | H8: Lagos
A9: 260307 | B9: IHEUKWUMERE FRIDAY KELECHI | C9: Fleet Supervisor Enugu | D9: - | E9: 44621 | F9: Fleet | G9: NETS | H9: Enugu
A10: 260308 | B10: TUMIE JOHNSON EKANMBAKUMO | C10: Fleet officer | D10: - | E10: 45352 | F10: Fleet | G10: NETS | H10: Lagos
A11: 260309 | B11: CHIDIMMA MAUREEN UZOUKWU | C11: NOC Supervisor | D11: - | E11: 45414 | F11: NOC | G11: NETS | H11: Lagos
A12: 260310 | B12: AREMU ABIODUN NAJEEM | C12: Fleet Supervisor Ibadan | D12: - | E12: 45329 | F12: Fleet | G12: NETS | H12: Ibadan
A13: 260311 | B13: BABALOLA IMOLEAYO ADELAKUN | C13: Fleet Supervisor NBC | D13: - | E13: 45350 | F13: Fleet | G13: NETS | H13: Benin
A14: 260312 | B14: OLUWASIJIBOMI EBENEZER AKINSOHUN | C14: Fleet Supervisor YNV | D14: - | E14: 45488 | F14: Fleet | G14: NETS | H14: Lagos
... A20: 260318 | B20: ADEFEHINTOYE ADEDEJI | C20: Fleet Supervisor I H S | D20: - | E20: 45702 | F20: Fleet | G20: NETS | H20: Lagos
A21: 260319 | B21: ODUBIYI OLUWASEUN | C21: Fleet Support Wasimi | D21: - | E21: March 17th 2025 | F21: Fleet | G21: NETS | H21: Ogun
A22: 260320 | B22: HELEN AJOKE JOHN | C22: BUS ASSISTANT | D22: - | E22: March 24th 2025 | F22: Fleet | G22: NETS | H22: Lagos
A23: 260321 | B23: AKANBI LATIFAT OMOLADE | C23: FLEET SUPERVISOR NBC | D23: - | E23: 45778 | F23: Fleet | G23: NETS | H23: Lagos
A24: 260322 | B24: FATAI ADEBULE | C24: MECHANIC | D24: - | E24: 45792 | F24: Fleet | G24: NETS | H24: Lagos
A25: 260323 | B25: DIVINE FAVOUR CHI EGBOMUCHE | C25: Head Of Marketing | D25: - | E25: 45870 | F25: Marketing | G25: NETS | H25: Lagos
A26: 260324 | B26: EGBA STELLA ADUTOMIVIE | C26: HR EXECUTIVE | D26: - | E26: 45870 | F26: Human Resources | G26: NETS | H26: Lagos
A27: 260325 | B27: ISAAC EKPO JAMES | C27: MARKETING EXECUTIVE | D27: - | E27: 45870 | F27: Marketing | G27: NETS | H27: Lagos
A28: 260326 | B28: KALU GIFT KELECHI | C28: HEAD HR | D28: - | E28: 45880 | F28: Human Resources | G28: NETS | H28: Lagos
A29: 260327 | B29: EKWEALOR OLUCHI UGOCHI | C29: Fleet Monitoring Officer NOC | D29: - | E29: 45884 | F29: NOC | G29: NETS | H29: Lagos
A30: 260328 | B30: ONEBUNNE GINIKA PERPETUS | C30: Fleet Monitoring Officer NOC | D30: - | E30: 45884 | F30: NOC | G30: NETS | H30: Lagos
A31: 260329 | B31: OGUNDIPE FEMI FELIX | C31: FINANCE ANALYST | D31: - | E31: 45901 | F31: Finance & Accounts | G31: NETS | H31: Lagos
A32: 260330 | B32: ANUCHA OLUEBUBE PRECIOUS | C32: OFFICE ASSISTANT | D32: - | E32: 45916 | F32: Admin/HR | G32: NETS | H32: Lagos
A33: 260331 | B33: IBEMERE ONYEKACHI PRECIOUS | C33: Fleet Monitoring Officer NOC | D33: - | E33: 45916 | F33: NOC | G33: NETS | H33: Lagos
A34: 260332 | B34: NWAOHA MICHAEL ONYEKWERE | C34: HSE EXECUTIVE | D34: - | E34: 45929 | F34: Fleet | G34: NETS | H34: Lagos
... A50: 260348 | B50: DAVID MBACHA | C50: ERP/IT Officer | D50: - | E50: 45677 | F50: Finance & Accounts | G50: NETS | H50: Lagos
A51: 260349 | B51: EMMAH JAMES EKANEM | C51: Workshop Staff | D51: - | E51: 1st Nov 2025 | F51: Workshop | G51: NETS | H51: Lagos
A52: 260350 | B52: ONYINYECHI NWOYE | C52: Office Assistant | D52: - | E52: 4th Feb 2026 | F52: Admin/HR | G52: NETS | H52: Lagos
A53: 260351 | B53: ABIDEEN AJISEGIRI | C53: Mechanic Intern | D53: - | E53: 1st Feb 2026 | F53: Workshop | G53: NETS | H53: Lagos
A54: 260352 | B54: ODO ABUCHI EMEKA | C54: Mechanic | D54: - | E54: 2nd March 2026 | F54: Workshop | G54: NETS | H54: Lagos
A55: 260353 | B55: Nwodo Julius Chukwujekwu | C55: Driver | D55: - | E55: 2nd March 2026 | F55: Fleet | G55: NETS | H55: Lagos
A56: 260354 | B56: MUSA BINTA | C56: Admin/Relationship Officer | D56: - | E56: 1st Feberuary 2019 | F56: KHLC/Skillup | G56: KHLC | H56: Lagos
A57: 260355 | B57: SOLOMON GRACE AMARACHI | C57: Program Coordinator | D57: - | E57: 25th October 2019 | F57: KHLC/Skillup | G57: KHLC | H57: Lagos
A58: 260356 | B58: BANWO IBISOLA YETUNDE | C58: Supervisor | D58: - | E58: 1st sep 2022 | F58: KHLC/Skillup | G58: KHLC | H58: Lagos
A59: 260357 | B59: LAWAL OBANLE PROMISE | C59: Head of Robotics | D59: - | E59: 2nd May 2024 | F59: KHLC/Skillup | G59: KHLC | H59: Lagos
A60: 260358 | B60: AKINWALE AKINOLA SAMSON | C60: Skill Up Coordinator | D60: - | E60: 1st May 2024 | F60: KHLC/Skillup | G60: KHLC | H60: Lagos
...
